#VRML_SIM R2019a utf8
WorldInfo {
}
Viewpoint {
  orientation 0.7806526829932567 0.5806998748728025 0.23101741029225803 6.187836773011079
  position 0.06500345535856002 0.9108336174006669 2.04377220777833
}
TexturedBackground {
}
TexturedBackgroundLight {
}
Floor {
}
Solid {
  rotation 0 1 0 -0.7853996938995746
  children [
    DEF BASE Group {
      children [
        DEF ONE Transform {
          translation 0.3 0.3 0
          rotation 0 0 1 0.2617996938995747
          children [
            Shape {
              appearance DEF BLUE PBRAppearance {
                baseColor 0.4470588235294118 0.6235294117647059 0.8117647058823529
                roughness 1
                metalness 0
              }
              geometry DEF CYLINDER_BASE Cylinder {
                height 0.6
                radius 0.019999999999999997
              }
            }
          ]
        }
        DEF ONE_FRONT Transform {
          translation -0.3 0.3 0
          rotation 0 0 1 -0.262
          children [
            Shape {
              appearance USE BLUE
              geometry USE CYLINDER_BASE
            }
          ]
        }
        DEF TWO Transform {
          translation 0 0.3 0.3
          rotation 1 0 0 -0.262
          children [
            Shape {
              appearance USE BLUE
              geometry USE CYLINDER_BASE
            }
          ]
        }
        DEF TWO_FRONT Transform {
          translation 0 0.3 -0.3
          rotation 1 0 0 0.262
          children [
            Shape {
              appearance USE BLUE
              geometry USE CYLINDER_BASE
            }
          ]
        }
        DEF OUT Transform {
          translation 0.15 0.3 0.149
          rotation 0.7071067811865475 0 0.7071067811865475 1.5708003061004252
          children [
            Shape {
              appearance USE BLUE
              geometry DEF SUPPORT Cylinder {
                height 0.4
                radius 0.019999999999999997
              }
            }
          ]
        }
        DEF OUT_FRONT Transform {
          translation -0.15 0.3000000397930553 -0.15
          rotation 0.7071067811865475 0 0.7071067811865475 1.5708003061004252
          children [
            Shape {
              appearance USE BLUE
              geometry USE SUPPORT
            }
          ]
        }
        DEF COUT_1 Transform {
          translation -0.1468519787567164 0.3000000027659453 0.1505025236085084
          rotation 0.3527265321748586 0.3527265321748586 -0.866699479058224 4.565413787860441
          children [
            Shape {
              appearance USE BLUE
              geometry USE SUPPORT
            }
          ]
        }
        DEF COUT_1FRONT Transform {
          translation 0.147 0.3 -0.151
          rotation 0.3527265321748586 0.3527265321748586 -0.866699479058224 4.565413787860441
          children [
            Shape {
              appearance USE BLUE
              geometry USE SUPPORT
            }
          ]
        }
        DEF BASE_BOX Transform {
          translation 0 0.6 0
          rotation 0 1 0 -0.7854003061004253
          children [
            Shape {
              appearance USE BLUE
              geometry Box {
                size 0.4 0.01 0.4
              }
            }
          ]
        }
      ]
    }
    Group {
      children [
        Solid {
          translation 0 0.7 0
          children [
            Shape {
              appearance DEF GREEN PBRAppearance {
                baseColor 0.5411764705882353 0.8862745098039215 0.20392156862745098
                roughness 1
                metalness 0
              }
              geometry Cylinder {
                height 0.2
                radius 0.05
              }
            }
            Transform {
              translation 0 0.15 0
              rotation 0 1 0 -0.7854003061004253
              children [
                Shape {
                  appearance USE GREEN
                  geometry Box {
                    size 0.5 0.1 0.1
                  }
                }
              ]
            }
          ]
          name "solid(1)"
          physics Physics {
          }
        }
      ]
    }
    HingeJoint {
      jointParameters HingeJointParameters {
        axis 0 1 0
        anchor -0.178 0.85 -0.178
        minStop -0.7854
        maxStop 0.7854
        springConstant 0.06667
      }
      endPoint Solid {
        translation -0.25999947425883857 0.8499988069690593 -0.2600005764877898
        rotation -6.814484893366915e-08 -0.999999999999984 1.648318094316829e-07 0.785406403126181
        children [
          Shape {
            appearance USE GREEN
            geometry DEF ASPA Box {
              size 0.25 0.05 0.02
            }
          }
        ]
        boundingObject USE ASPA
        physics Physics {
        }
      }
    }
    HingeJoint {
      jointParameters HingeJointParameters {
        axis 1 0 1
        anchor 0.178 0.85 0.178
      }
      endPoint Solid {
        translation 0.18 0.85 0.18
        rotation 0 1 0 0.7854000000000001
        children [
          DEF OLO Group {
            children [
              Shape {
                appearance USE GREEN
                geometry DEF HELIX Box {
                  size 0.01 0.35 0.01
                }
              }
              Transform {
                rotation 0 0 1 0.7854
                children [
                  Shape {
                    appearance USE GREEN
                    geometry USE HELIX
                  }
                ]
              }
              Transform {
                rotation 0 0 1 -0.7854
                children [
                  Shape {
                    appearance USE GREEN
                    geometry USE HELIX
                  }
                ]
              }
              Transform {
                rotation 0 0 1 1.57
                children [
                  Shape {
                    appearance USE GREEN
                    geometry USE HELIX
                  }
                ]
              }
            ]
          }
        ]
        name "solid(2)"
        boundingObject USE OLO
        physics Physics {
          density 500
        }
      }
    }
  ]
  boundingObject USE BASE
  physics Physics {
  }
}
