#VRML_SIM R2019a utf8
WorldInfo {
}
Viewpoint {
  orientation 0.035171788779794905 -0.9366313982370106 -0.3485463657974533 3.330063584948404
  position 0.09186058304386868 1.7823418143460708 -1.2922779155805875
}
TexturedBackground {
}
TexturedBackgroundLight {
}
Floor {
}
Solid {
  children [
    Group {
      children [
        Group {
          children [
            DEF ONE Transform {
              translation 0.3 0.3 0
              rotation 0 0 1 0.2617996938995747
              children [
                Shape {
                  appearance DEF BLUE PBRAppearance {
                    baseColor 0.4470588235294118 0.6235294117647059 0.8117647058823529
                    roughness 1
                    metalness 0
                  }
                  geometry DEF CYLINDER_BASE Cylinder {
                    height 0.6
                    radius 0.02
                  }
                }
              ]
            }
            DEF ONE_FRONT Transform {
              translation -0.3 0.3 0
              rotation 0 0 1 -0.262
              children [
                Shape {
                  appearance DEF BLUE PBRAppearance {
                    baseColor 0.4470588235294118 0.6235294117647059 0.8117647058823529
                    roughness 1
                    metalness 0
                  }
                  geometry DEF CYLINDER_BASE Cylinder {
                    height 0.6
                    radius 0.02
                  }
                }
              ]
            }
            DEF TWO Transform {
              translation 0 0.3 0.3
              rotation 1 0 0 -0.262
              children [
                Shape {
                  appearance DEF BLUE PBRAppearance {
                    baseColor 0.4470588235294118 0.6235294117647059 0.8117647058823529
                    roughness 1
                    metalness 0
                  }
                  geometry DEF CYLINDER_BASE Cylinder {
                    height 0.6
                    radius 0.02
                  }
                }
              ]
            }
            DEF TWO_FRONT Transform {
              translation 0 0.3 -0.3
              rotation 1 0 0 0.262
              children [
                Shape {
                  appearance DEF BLUE PBRAppearance {
                    baseColor 0.4470588235294118 0.6235294117647059 0.8117647058823529
                    roughness 1
                    metalness 0
                  }
                  geometry DEF CYLINDER_BASE Cylinder {
                    height 0.6
                    radius 0.02
                  }
                }
              ]
            }
            DEF OUT Transform {
              translation 0.15 0.3 0.149
              rotation 0.7071067811865475 0 0.7071067811865475 1.5708003061004252
              children [
                Shape {
                  appearance USE BLUE
                  geometry DEF OUT_CYLINDER Cylinder {
                    height 0.4
                    radius 0.02
                  }
                }
              ]
            }
            DEF OUT_FRONT Transform {
              translation -0.15 0.3000000397930553 -0.15
              rotation 0.7071067811865475 0 0.7071067811865475 1.5708003061004252
              children [
                Shape {
                  appearance USE BLUE
                  geometry Cylinder {
                    height 0.4
                    radius 0.02
                  }
                }
              ]
            }
            DEF COUT_1 Transform {
              translation -0.1468519787567164 0.3000000027659453 0.1505025236085084
              rotation 0.3527265321748586 0.3527265321748586 -0.866699479058224 4.565413787860441
              children [
                Shape {
                  appearance USE BLUE
                  geometry USE OUT_CYLINDER
                }
              ]
            }
            DEF COUT_1FRONT Transform {
              translation 0.147 0.3 -0.151
              rotation 0.3527265321748586 0.3527265321748586 -0.866699479058224 4.565413787860441
              children [
                Shape {
                  appearance USE BLUE
                  geometry USE OUT_CYLINDER
                }
              ]
            }
            DEF BASE_BOX Transform {
              translation 0 0.6 0
              rotation 0 1 0 -0.7854003061004253
              children [
                Shape {
                  appearance USE BLUE
                  geometry Box {
                    size 0.4 0.01 0.4
                  }
                }
              ]
            }
          ]
        }
        Group {
          children [
            Solid {
              translation 0 0.7 0
              children [
                Shape {
                  appearance DEF GREEN PBRAppearance {
                    baseColor 0.5411764705882353 0.8862745098039215 0.20392156862745098
                    roughness 1
                    metalness 0
                  }
                  geometry Cylinder {
                    height 0.2
                    radius 0.03
                  }
                }
                Transform {
                  translation 0 0.15 0
                  rotation 0 1 0 -0.7854003061004253
                  children [
                    Shape {
                      appearance USE GREEN
                      geometry Box {
                        size 0.3 0.1 0.1
                      }
                    }
                  ]
                }
              ]
            }
          ]
        }
        HingeJoint {
          jointParameters HingeJointParameters {
            axis 0 1 0
            anchor 0.256 0.85 0.24
            minStop -0.7854
            maxStop 0.7854
            dampingConstant 2
          }
          endPoint Solid {
            children [
              Group {
                children [
                  Transform {
                    translation 0.256 0.85 0.24
                    rotation -0.29912070340549424 0.6747320967592257 -0.6747320967592257 3.6896201326638907
                    children [
                      Shape {
                        appearance USE GREEN
                        geometry Cylinder {
                          height 0.4
                          radius 0.019999999999999997
                        }
                      }
                    ]
                  }
                ]
              }
              HingeJoint {
                jointParameters HingeJointParameters {
                  anchor -0.108 0.85 -0.118
                }
                endPoint Solid {
                  translation -8.240945559429003e-07 -1.609746402342349e-05 -9.083233308559979e-07
                  rotation 0.7393790489102685 -0.010484829009624714 -0.6732077616851918 2.5101270305212674e-06
                  children [
                    Group {
                      children [
                        Transform {
                          translation -0.10772077954769858 0.8500000017566348 -0.11788157969516588
                          rotation 0.8628562117939189 -0.35740674409112405 -0.3574067389499388 4.565413778166129
                          children [
                            DEF ASPA Shape {
                              appearance USE GREEN
                              geometry Box {
                                size 0.6 0.02 0.06
                              }
                            }
                          ]
                        }
                        Transform {
                          translation -0.10800000000000001 0.85 -0.118
                          rotation 0.6785983457559442 0.6785983438499072 0.281084636473534 2.5935642397409957
                          children [
                            USE ASPA
                          ]
                        }
                      ]
                    }
                  ]
                  physics Physics {
                  }
                }
              }
            ]
            name "solid(1)"
            physics Physics {
            }
          }
        }
      ]
    }
  ]
}
